Workbook

Sheet Ref
A1: No | B1: Nama BPR | C1: Margin | D1: Jasa Fronting Agent | E1: Biaya Admin | F1: Biaya Provisi | G1: Tabel Asuransi | H1: Biaya Asuransi | J1: Kode | K1: Marketing | V1: KPRK | W1: KPC | X1: TARGET FA | Y1: TODAY | Z1: TGL. LAHIR DEB. | AA1: BY MUTASI | AC1: PLATINUM
U2: REG V | V2: BANYUWANGI | W2: 17 | Y2: =DAY(Y5) -> 24 | Z2: =DATE('Simulasi BPR'!G7,'Simulasi BPR'!F7,'Simulasi BPR'!E7) -> 19072 | AA2: 200000 | AC2: 17
A3: 1 | B3: BPR Kota Madiun | C3: 0.009 | D3: 0.06 | E3: 0.005 | F3: 0.005 | G3: =IF('Simulasi BPR'!C6="PLATINUM",(Asuransi!$V$11*(100%-Ref!AC31)),IF('Simulasi BPR'!C6="VETERAN",(Asuransi!$V$35*(100%-Ref!AC31)),"")) -> 0.255 | H3: =D3+G3 -> 0.315 | J3: 101 | K3: Elvira | U3: REG V | V3: JEMBER | W3: 25 | Y3: =MONTH(Y5) -> 8 | Z3: =(DATEDIF(Z2,Y5,"m"))/12 -> 74.416667 | AC3: 85
A4: 2 | E4: 0.01 | F4: 0.01 | J4: 102 | K4: Dody | U4: REG V | V4: BLITAR | W4: 18 | Y4: =YEAR(Y5) -> 2026 | Z4: =IF('Simulasi BPR'!J7<5,'Simulasi BPR'!I7,'Simulasi BPR'!I7+1) -> 75 | AC4: =AC3-'Simulasi BPR'!$I$7 -> 11
A5: 3 | J5: 103 | K5: MPA | U5: REG V | V5: KEDIRI | W5: 23 | Y5: =NOW() -> 46258.478
A6: 4 | J6: 104 | K6: Pak Rofiq | U6: REG V | V6: NGANJUK | W6: 18 | AB6: MAK. TENOR | AC6: =IF(OR('Simulasi BPR'!C7="BPR Kota Madiun",'Simulasi BPR'!C7="BPRS Bhakti Sumekar"),120,120) -> 120
A7: 5 | J7: 105 | K7: Hendra | N7: RATE(TENOR;(1*(1,1667%))+(1/TENOR);-1;0;0;1)*12 | U7: REG V | V7: TULUNGAGUNG | W7: 30 | Y7: STATUS ANALISA | AC7: =MAX(0,84*12+11-(DATEDIF(DATE('Simulasi BPR'!$G$7,'Simulasi BPR'!$F$7,'Simulasi BPR'!$E$7),TODAY(),"y")*12+DATEDIF(DATE('Simulasi BPR'!$G$7,'Simulasi BPR'!$F$7,'Simulasi BPR'!$E$7),TODAY(),"ym"))) -> 126
A8: 6 | B8: Tabel asuransi | C8: =$G$3 -> 0.255 | J8: 201 | K8: Bhakti Sumekar | U8: REG V | V8: BANGKALAN | W8: 24 | Y8: =IF('Simulasi BPR'!G13>AC10,("OVER"),("OK")) -> OK | AC8: =DATEDIF(DATE('Simulasi BPR'!$G$7,'Simulasi BPR'!$F$7,'Simulasi BPR'!$E$7),TODAY(),"y")+DATEDIF(DATE('Simulasi BPR'!$G$7,'Simulasi BPR'!$F$7,'Simulasi BPR'!$E$7),TODAY(),"ym")/12 -> 74.416667
A9: 7 | B9: Asuransi | C9: =$H$3 -> 0.315 | J9: 202 | K9: BSI Pamekasan | M9: jenis pen | U9: REG V | V9: PAMEKASAN | W9: 13 | Y9: =IF('Simulasi BPR'!J13>'Simulasi BPR'!J10,("OVER"),("OK")) -> OK | AC9: =MIN(AC6,AC7) -> 120
A10: 8 | B10: Fee Fronting | C10: =$D$3 -> 0.06 | J10: 203 | K10: E | M10: ='Simulasi BPR'!C16 -> TASPEN | O10: round tahun jkw | Q10: biaya | U10: REG V | V10: SUMENEP | W10: 18 | Y10: =IF(OR('Simulasi BPR'!M13>90%,'Simulasi BPR'!I7>Ref!AC3,'Simulasi BPR'!J13>Ref!AC12,'Simulasi BPR'!G13>Ref!AC10),"OVER","OK") -> OK | Z10: Admin | AA10: Provisi | AC10: =IF(AC8<85,AC9,0) -> 120
A11: 9 | B11: +MPA/Dody | C11: =IF(OR('Simulasi BPR'!$F$4=Ref!$J$4,'Simulasi BPR'!F4=Ref!$J$5),2%,0%) -> 0 | J11: 204 | K11: F | M11: ='Simulasi BPR'!G13 -> 120 | N11: =M11/12 -> 10 | O11: =ROUNDUP(N11,0) -> 10 | Q11: =IF(M10="ASABRI",300000,60000*O11) -> 600000 | U11: REG V | V11: LUMAJANG | W11: 15 | Y11: BPR Perdana | Z11: 0.01 | AA11: 0.01
A12: 10 | B12: premi Jamkrida | C12: =0.4%*$O$11 -> 0.04 | J12: 205 | K12: G | U12: REG V | V12: MALANG | W12: 36 | AB12: MAK. PLAFON | AC12: =IF(OR('Simulasi BPR'!C7="BPR KOTA MADIUN",'Simulasi BPR'!C7="BPRS Bhakti Sumekar"),200000000,150000000) -> 200000000
A13: 11 | B13: Pencadangan | C13: =C9-SUM(C10:C12) -> 0.215 | U13: REG V | V13: PASURUAN | W13: 18 | Y13: =IF('Simulasi BPR'!C7="BPR KOTA MADIUN",200000000,150000000) -> 200000000 | AC13: =IF(AC8<AC2,0,IF(AC8<AC3,AC12,IF(AC8>=AC3,0))) -> 200000000
A14: 12 | B14: margin 1 tahun | C14: =C3*12 -> 0.108 | D14: =C17*'Simulasi BPR'!J13 -> 0 | U14: REG V | V14: PROBOLINGGO | W14: 15 | Y14: =IF('Simulasi BPR'!C7="BPR KOTA MADIUN",180,120) -> 180 | AB14: MAK. ANGSURAN + EPOT | AC14: ='Simulasi BPR'!$F$10*90% -> 1575000
A15: 13 | U15: REG V | V15: BOJONEGORO | W15: 11 | Z15: =IF($AC$10<=Asuransi!C3,Asuransi!C3,IF($AC$10<Asuransi!D3,Asuransi!C3,IF($AC$10<Asuransi!E3,Asuransi!D3,IF($AC$10<Asuransi!F3,Asuransi!E3,IF($AC$10<Asuransi!G3,Asuransi!F3,IF($AC$10<Asuransi!H3,Asuransi!G3,IF($AC$10<Asuransi!I3,Asuransi!H3,IF($AC$10<Asuransi!J3,Asuransi!I3,IF($AC$10<Asuransi!K3,Asuransi!J3,IF($AC$10<Asuransi!L3,Asuransi!K3,IF($AC$10<Asuransi!M3,Asuransi!L3,IF($AC$10<Asuransi!N3,Asuransi!M3,IF($AC$10<Asuransi!O3,Asuransi!N3,IF($AC$10<Asuransi!P3,Asuransi!O3,0)))))))))))))) -> 0 | AB15: MAK. ANGSURAN | AC15: =AC14*90% -> 1417500
A16: 14 | U16: REG V | V16: JOMBANG | W16: 18 | Z16: =ROUNDUP('Simulasi BPR'!G13/12,0) -> 10
A17: 15 | U17: REG V | V17: LAMONGAN | W17: 12 | Z17: =IF('Simulasi BPR'!J7<6,'Simulasi BPR'!I7,'Simulasi BPR'!I7+1) -> 74 | AA17: =IF('Simulasi BPR'!C5=N37,R37,IF('Simulasi BPR'!C5=N38,R38,IF('Simulasi BPR'!C5=N39,R39,IF('Simulasi BPR'!C5=N40,R40,IF('Simulasi BPR'!C5=N41,R41,IF('Simulasi BPR'!C5=N42,R42,IF('Simulasi BPR'!C5=N43,R43,IF('Simulasi BPR'!C5=N44,R44,IF('Simulasi BPR'!C5=N45,R45,IF('Simulasi BPR'!C5=N46,R46,IF('Simulasi BPR'!C5=N47,R47,IF('Simulasi BPR'!C5=N48,R48,IF('Simulasi BPR'!C5=N49,R49,IF('Simulasi BPR'!C5=N50,R50,IF('Simulasi BPR'!C5=N51,R51))))))))))))))) -> FALSE | AB17: MAKS. PLAFON (FLAT) | AC17: =(AC14*'Simulasi BPR'!G13)/(1+(C3*'Simulasi BPR'!G13)) -> 90865385
U18: REG V | V18: LAMONGAN | W18: 12 | AA18: =IF('Simulasi BPR'!C6=N38,R38,IF('Simulasi BPR'!C6=N39,R39,IF('Simulasi BPR'!C6=N40,R40,IF('Simulasi BPR'!C6=N41,R41,IF('Simulasi BPR'!C6=N42,R42,IF('Simulasi BPR'!C6=N43,R43,IF('Simulasi BPR'!C6=N44,R44,IF('Simulasi BPR'!C6=N45,R45,IF('Simulasi BPR'!C6=N46,R46,IF('Simulasi BPR'!C6=N47,R47,IF('Simulasi BPR'!C6=N48,R48,IF('Simulasi BPR'!C6=N49,R49,IF('Simulasi BPR'!C6=N50,R50,IF('Simulasi BPR'!C6=N51,R51,IF('Simulasi BPR'!C6=N52,R52))))))))))))))) -> FALSE | AC18: =FLOOR(IF(AC17<=AC13,AC17,AC13),100000) -> 90800000
U19: REG V | V19: LAMONGAN | W19: 12 | AA19: =IF('Simulasi BPR'!C7=N39,R39,IF('Simulasi BPR'!C7=N40,R40,IF('Simulasi BPR'!C7=N41,R41,IF('Simulasi BPR'!C7=N42,R42,IF('Simulasi BPR'!C7=N43,R43,IF('Simulasi BPR'!C7=N44,R44,IF('Simulasi BPR'!C7=N45,R45,IF('Simulasi BPR'!C7=N46,R46,IF('Simulasi BPR'!C7=N47,R47,IF('Simulasi BPR'!C7=N48,R48,IF('Simulasi BPR'!C7=N49,R49,IF('Simulasi BPR'!C7=N50,R50,IF('Simulasi BPR'!C7=N51,R51,IF('Simulasi BPR'!C7=N52,R52,IF('Simulasi BPR'!C7=N53,R53))))))))))))))) -> 0.16926681 | AB19: MAKS. PLAFON | AC19: =PV(AA19/12,'Simulasi BPR'!$G$13,AC14)*-1 -> 90865385
U20: REG V | V20: SIDOARJO | W20: 17 | AC20: =FLOOR(IF(AC19<=AC13,AC19,AC13),100000) -> 90800000
U21: REG V | V21: TUBAN | W21: 11
AA22: =(((AC22*'Simulasi BPR'!G13)-'Simulasi BPR'!J13)/'Simulasi BPR'!G13)/'Simulasi BPR'!J13 -> 0.0098350661 | AB22: Angsuran + EPOT | AC22: =IF('Simulasi BPR'!C18="POS",(PMT(AA19/12,'Simulasi BPR'!$G$13,'Simulasi BPR'!$J$13)*-1)*$AA$35+$AA$30,IF('Simulasi BPR'!C18="Mantap",(PMT(AA19/12,'Simulasi BPR'!$G$13,'Simulasi BPR'!$J$13)*-1)*$AA$44+$AA$39,IF('Simulasi BPR'!C18="BSI",(PMT(AA19/12,'Simulasi BPR'!$G$13,'Simulasi BPR'!$J$13)*-1)*$AA$53+$AA$48,""))) -> 1649690.7 | AE22: Angsuran + EPOT
U23: REG V | V23: DENPASAR | W23: 19 | AA23: =RATE('Simulasi BPR'!G13,(1*(AA22))+(1/'Simulasi BPR'!G13),-1,0,0,1)*12 -> 0.18232391 | AB23: EPOT | AC23: =IF('Simulasi BPR'!C18="POS",(PMT(AA19/12,'Simulasi BPR'!$G$13,'Simulasi BPR'!$J$13)*-1)*$AA$35*$AA$34+$AA$30,IF('Simulasi BPR'!C18="Mantap",(PMT(AA19/12,'Simulasi BPR'!$G$13,'Simulasi BPR'!$J$13)*-1)*$AA$44*$AA$43+$AA$39,IF('Simulasi BPR'!C18="BSI",(PMT(AA19/12,'Simulasi BPR'!$G$13,'Simulasi BPR'!$J$13)*-1)*$AA$53*$AA$352+$AA$48,""))) -> 79011.08
U24: REG V | V24: GIANYAR | W24: 23 | AA24: =(((AC24*'Simulasi BPR'!G13)-'Simulasi BPR'!J13)/'Simulasi BPR'!G13)/'Simulasi BPR'!J13 -> 0.0089649 | AB24: Angsuran | AC24: =AC22-AC23 -> 1570679.6
U25: REG V | V25: SINGARAJA | W25: 10 | AA25: =RATE('Simulasi BPR'!G13,(1*(AA24))+(1/'Simulasi BPR'!G13),-1,0,0,1)*12 -> 0.16871197
U26: REG V | V26: TABANAN | W26: 12 | AB26: =AC26+5000 -> 3392092.6 | AC26: 3387092.6
AB27: =AC27+5000 -> 208225.56 | AC27: =AC26*6% -> 203225.56
U28: REG V | V28: KUPANG | W28: 16 | AC28: 3183867
Z29: POS
U30: REG VI | V30: BALIKPAPAN | W30: 11 | Z30: extra fee | AA30: 5000
Z31: fee postra | AA31: 0.01 | AB31: Diskon tabel | AC31: 0
U32: REG VI | V32: MAKASAR | W32: 24 | Z32: fee bgp | AA32: 0.01
U33: REG VI | V33: PALU | W33: 42 | Z33: fee pos | AA33: =4%*111% -> 0.0444
U34: REG VI | V34: KENDARI | W34: 38 | Z34: total fee | AA34: =SUM(AA31:AA33) -> 0.0644
U35: REG VI | V35: MANADO | W35: 46 | Z35: multiplier % | AA35: =1+AA34 -> 1.0644
Z36: multiplier num | AA36: =AA35 -> 1.0644
Q37: JUAL BPR | R37: JUAL BPR | S37: Admin | T37: Provisi | U37: REG VI | V37: AMBOINA | W37: 22
M38: VENDOR BPR: | Q38: FLAT | R38: EFEKTIF | Z38: Mantap
M39: 1 | N39: BPR DAYA PERDANA NUSANTARA | Q39: 0.01 | R39: =RATE('Simulasi BPR'!$G13,(1*(Q39))+(1/'Simulasi BPR'!$G13),-1,0,0,1)*12 -> 0.18487173 | S39: 0.01 | T39: 0.01 | Z39: extra fee | AA39: 5000
M40: 2 | N40: BPR BINTANG MITRA | Q40: 0.01 | R40: =RATE('Simulasi BPR'!$G13,(1*(Q40))+(1/'Simulasi BPR'!$G13),-1,0,0,1)*12 -> 0.18487173 | S40: 0.01 | T40: 0.01 | Z40: fee ? | AA40: 0
...

Sheet Asuransi
B2: USIA | J2: TENOR
B3: MASUK | C3: 1 | D3: 2 | E3: 3 | F3: 4 | G3: 5 | H3: 6 | I3: 7 | J3: 8 | K3: 9 | L3: 10 | M3: 11 | N3: 12 | O3: 13 | P3: 14 | Q3: 15 | R3: =IF(Ref!$Z$4<=B5,R5,IF(Ref!$Z$4=B6,R6,IF(Ref!$Z$4=B7,R7,IF(Ref!$Z$4=B8,R8,IF(Ref!$Z$4=B9,R9,IF(Ref!$Z$4=B10,R10,IF(Ref!$Z$4=B11,R11,IF(Ref!$Z$4=B12,R12,IF(Ref!$Z$4=B13,R13,IF(Ref!$Z$4=B14,R14,IF(Ref!$Z$4=B15,R15,IF(Ref!$Z$4=B16,R16,IF(Ref!$Z$4=B17,R17,IF(Ref!$Z$4=B18,R18,IF(Ref!$Z$4=B19,R19,IF(Ref!$Z$4=B20,R20,IF(Ref!$Z$4=B21,R21,IF(Ref!$Z$4=B22,R22,IF(Ref!$Z$4=B23,R23,IF(Ref!$Z$4=B24,R24,IF(Ref!$Z$4<80,R24))))))))))))))))))))) -> 0.255 | T3: 12 | U3: 24 | V3: 36 | W3: 48 | X3: 60 | Y3: 72 | Z3: 84 | AA3: 96 | AB3: 108 | AC3: 120
B5: 65 | C5: =ROUNDUP('[1]Asuransi Original'!C5*75%,4) -> 0.0049 | D5: =ROUNDUP('[1]Asuransi Original'!D5*75%,4) -> 0.0098 | E5: =ROUNDUP('[1]Asuransi Original'!E5*75%,4) -> 0.0147 | F5: =ROUNDUP('[1]Asuransi Original'!F5*75%,4) -> 0.0195 | G5: =ROUNDUP('[1]Asuransi Original'!G5*75%,4) -> 0.0244 | H5: =ROUNDUP('[1]Asuransi Original'!H5*75%,4) -> 0.0508 | I5: =ROUNDUP('[1]Asuransi Original'!I5*75%,4) -> 0.0615 | J5: =ROUNDUP('[1]Asuransi Original'!J5*75%,4) -> 0.0743 | ... Q5: =ROUNDUP('[1]Asuransi Original'!Q5*75%,4) -> 0.192 | R5: =IF(Ref!$Z$16<=$C$3,C5,IF(Ref!$Z$16<$D$3,C5,IF(Ref!$Z$16<$E$3,D5,IF(Ref!$Z$16<$F$3,E5,IF(Ref!$Z$16<$G$3,F5,IF(Ref!$Z$16<$H$3,G5,(IF(Ref!$Z$16<$I$3,H5,IF(Ref!$Z$16<$J$3,I5,IF(Ref!$Z$16<$K$3,J5,IF(Ref!$Z$16<$L$3,K5,IF(Ref!$Z$16<$M$3,L5,IF(Ref!$Z$16<$N$3,M5,IF(Ref!$Z$16<$O$3,N5,IF(Ref!$Z$16<$P$3,O5,IF(Ref!$Z$16<$Q$3,P5,IF(Ref!$Z$16<=$Q$3,Q5))))))))))))))))) -> 0.0923 | S5: 70 - 74 | T5: 0.06069 | U5: 0.09136 | V5: 0.12993 | W5: 0.16079 | X5: 0.19357 | Y5: 0.22025 | Z5: 0.24371 | AA5: 0.26686 | AB5: 0.28807 | AC5: 0.29932
B6: 66 | C6: =ROUNDUP('[1]Asuransi Original'!C6*75%,4) -> 0.0049 | D6: =ROUNDUP('[1]Asuransi Original'!D6*75%,4) -> 0.0098 | E6: =ROUNDUP('[1]Asuransi Original'!E6*75%,4) -> 0.0147 | F6: =ROUNDUP('[1]Asuransi Original'!F6*75%,4) -> 0.0195 | G6: =ROUNDUP('[1]Asuransi Original'!G6*75%,4) -> 0.0459 | H6: =ROUNDUP('[1]Asuransi Original'!H6*75%,4) -> 0.0567 | I6: =ROUNDUP('[1]Asuransi Original'!I6*75%,4) -> 0.0694 | J6: =ROUNDUP('[1]Asuransi Original'!J6*75%,4) -> 0.075 | ... P6: =ROUNDUP('[1]Asuransi Original'!P6*75%,4) -> 0.1902 | Q6: 0 | R6: =IF(Ref!$Z$16<=$C$3,C6,IF(Ref!$Z$16<$D$3,C6,IF(Ref!$Z$16<$E$3,D6,IF(Ref!$Z$16<$F$3,E6,IF(Ref!$Z$16<$G$3,F6,IF(Ref!$Z$16<$H$3,G6,(IF(Ref!$Z$16<$I$3,H6,IF(Ref!$Z$16<$J$3,I6,IF(Ref!$Z$16<$K$3,J6,IF(Ref!$Z$16<$L$3,K6,IF(Ref!$Z$16<$M$3,L6,IF(Ref!$Z$16<$N$3,M6,IF(Ref!$Z$16<$O$3,N6,IF(Ref!$Z$16<$P$3,O6,IF(Ref!$Z$16<$Q$3,P6,IF(Ref!$Z$16<=$Q$3,Q6))))))))))))))))) -> 0.1662 | T6: 0.065 | U6: 0.11 | V6: 0.15179 | W6: 0.195 | X6: 0.23921 | Y6: 0 | Z6: 0 | AA6: 0 | AB6: 0 | AC6: 0
B7: 67 | C7: =ROUNDUP('[1]Asuransi Original'!C7*75%,4) -> 0.0049 | D7: =ROUNDUP('[1]Asuransi Original'!D7*75%,4) -> 0.0098 | E7: =ROUNDUP('[1]Asuransi Original'!E7*75%,4) -> 0.0147 | F7: =ROUNDUP('[1]Asuransi Original'!F7*75%,4) -> 0.0411 | G7: =ROUNDUP('[1]Asuransi Original'!G7*75%,4) -> 0.0518 | H7: =ROUNDUP('[1]Asuransi Original'!H7*75%,4) -> 0.0645 | I7: =ROUNDUP('[1]Asuransi Original'!I7*75%,4) -> 0.0702 | J7: =ROUNDUP('[1]Asuransi Original'!J7*75%,4) -> 0.0825 | ... O7: =ROUNDUP('[1]Asuransi Original'!O7*75%,4) -> 0.1812 | P7: 0 | Q7: 0 | R7: =IF(Ref!$Z$16<=$C$3,C7,IF(Ref!$Z$16<$D$3,C7,IF(Ref!$Z$16<$E$3,D7,IF(Ref!$Z$16<$F$3,E7,IF(Ref!$Z$16<$G$3,F7,IF(Ref!$Z$16<$H$3,G7,(IF(Ref!$Z$16<$I$3,H7,IF(Ref!$Z$16<$J$3,I7,IF(Ref!$Z$16<$K$3,J7,IF(Ref!$Z$16<$L$3,K7,IF(Ref!$Z$16<$M$3,L7,IF(Ref!$Z$16<$N$3,M7,IF(Ref!$Z$16<$O$3,N7,IF(Ref!$Z$16<$P$3,O7,IF(Ref!$Z$16<$Q$3,P7,IF(Ref!$Z$16<=$Q$3,Q7))))))))))))))))) -> 0.1737 | T7: 75-79 | U7: 75-78 | V7: 75-77 | W7: 75-76 | X7: 75-75
B8: 68 | C8: =ROUNDUP('[1]Asuransi Original'!C8*75%,4) -> 0.0049 | D8: =ROUNDUP('[1]Asuransi Original'!D8*75%,4) -> 0.0098 | E8: =ROUNDUP('[1]Asuransi Original'!E8*75%,4) -> 0.0362 | F8: =ROUNDUP('[1]Asuransi Original'!F8*75%,4) -> 0.0469 | G8: =ROUNDUP('[1]Asuransi Original'!G8*75%,4) -> 0.0597 | H8: =ROUNDUP('[1]Asuransi Original'!H8*75%,4) -> 0.0653 | I8: =ROUNDUP('[1]Asuransi Original'!I8*75%,4) -> 0.0777 | J8: =ROUNDUP('[1]Asuransi Original'!J8*75%,4) -> 0.1662 | ... N8: =ROUNDUP('[1]Asuransi Original'!N8*75%,4) -> 0.1887 | O8: 0 | P8: 0 | Q8: 0 | R8: =IF(Ref!$Z$16<=$C$3,C8,IF(Ref!$Z$16<$D$3,C8,IF(Ref!$Z$16<$E$3,D8,IF(Ref!$Z$16<$F$3,E8,IF(Ref!$Z$16<$G$3,F8,IF(Ref!$Z$16<$H$3,G8,(IF(Ref!$Z$16<$I$3,H8,IF(Ref!$Z$16<$J$3,I8,IF(Ref!$Z$16<$K$3,J8,IF(Ref!$Z$16<$L$3,K8,IF(Ref!$Z$16<$M$3,L8,IF(Ref!$Z$16<$N$3,M8,IF(Ref!$Z$16<$O$3,N8,IF(Ref!$Z$16<$P$3,O8,IF(Ref!$Z$16<$Q$3,P8,IF(Ref!$Z$16<=$Q$3,Q8))))))))))))))))) -> 0.1774
B9: 69 | C9: =ROUNDUP('[1]Asuransi Original'!C9*75%,4) -> 0.0049 | D9: =ROUNDUP('[1]Asuransi Original'!D9*75%,4) -> 0.0313 | E9: =ROUNDUP('[1]Asuransi Original'!E9*75%,4) -> 0.042 | F9: =ROUNDUP('[1]Asuransi Original'!F9*75%,4) -> 0.0548 | G9: =ROUNDUP('[1]Asuransi Original'!G9*75%,4) -> 0.0604 | H9: =ROUNDUP('[1]Asuransi Original'!H9*75%,4) -> 0.0728 | I9: =ROUNDUP('[1]Asuransi Original'!I9*75%,4) -> 0.1692 | J9: =ROUNDUP('[1]Asuransi Original'!J9*75%,4) -> 0.1737 | ... M9: =ROUNDUP('[1]Asuransi Original'!M9*75%,4) -> 0.1864 | N9: 0 | O9: 0 | P9: 0 | Q9: 0 | R9: =IF(Ref!$Z$16<=$C$3,C9,IF(Ref!$Z$16<$D$3,C9,IF(Ref!$Z$16<$E$3,D9,IF(Ref!$Z$16<$F$3,E9,IF(Ref!$Z$16<$G$3,F9,IF(Ref!$Z$16<$H$3,G9,(IF(Ref!$Z$16<$I$3,H9,IF(Ref!$Z$16<$J$3,I9,IF(Ref!$Z$16<$K$3,J9,IF(Ref!$Z$16<$L$3,K9,IF(Ref!$Z$16<$M$3,L9,IF(Ref!$Z$16<$N$3,M9,IF(Ref!$Z$16<$O$3,N9,IF(Ref!$Z$16<$P$3,O9,IF(Ref!$Z$16<$Q$3,P9,IF(Ref!$Z$16<=$Q$3,Q9))))))))))))))))) -> 0.1812 | S9: AA7 | T9: =IF('Simulasi BPR'!$I$7<=65,65,'Simulasi BPR'!I7) -> 74 | U9: =Ref!$Z$16 -> 10 | V9: =INDEX($C$5:$Q$24,MATCH($T9,$B$5:$B$24,0),MATCH($U9,$C$3:$Q$3,0)) -> 0.24
B10: 70 | C10: =ROUNDUP('[1]Asuransi Original'!C10*75%,4) -> 0.0264 | D10: =ROUNDUP('[1]Asuransi Original'!D10*75%,4) -> 0.0327 | E10: =ROUNDUP('[1]Asuransi Original'!E10*75%,4) -> 0.0499 | F10: =ROUNDUP('[1]Asuransi Original'!F10*75%,4) -> 0.0555 | G10: =ROUNDUP('[1]Asuransi Original'!G10*75%,4) -> 0.0679 | H10: =ROUNDUP('[1]Asuransi Original'!H10*75%,4) -> 0.1617 | I10: =ROUNDUP('[1]Asuransi Original'!I10*75%,4) -> 0.1714 | J10: =ROUNDUP('[1]Asuransi Original'!J10*75%,4) -> 0.1759 | ... L10: =ROUNDUP('[1]Asuransi Original'!L10*75%,4) -> 0.1834 | M10: 0 | N10: 0 | O10: 0 | P10: 0 | Q10: 0 | R10: =IF(Ref!$Z$16<=$C$3,C10,IF(Ref!$Z$16<$D$3,C10,IF(Ref!$Z$16<$E$3,D10,IF(Ref!$Z$16<$F$3,E10,IF(Ref!$Z$16<$G$3,F10,IF(Ref!$Z$16<$H$3,G10,(IF(Ref!$Z$16<$I$3,H10,IF(Ref!$Z$16<$J$3,I10,IF(Ref!$Z$16<$K$3,J10,IF(Ref!$Z$16<$L$3,K10,IF(Ref!$Z$16<$M$3,L10,IF(Ref!$Z$16<$N$3,M10,IF(Ref!$Z$16<$O$3,N10,IF(Ref!$Z$16<$P$3,O10,IF(Ref!$Z$16<$Q$3,P10,IF(Ref!$Z$16<=$Q$3,Q10))))))))))))))))) -> 0.1834 | S10: AA7+1 | T10: =T9+1 -> 75 | U10: =Ref!$Z$16 -> 10 | V10: =INDEX($C$5:$Q$24,MATCH($T10,$B$5:$B$24,0),MATCH($U10,$C$3:$Q$3,0)) -> 0.255
B11: 71 | C11: =ROUNDUP('[1]Asuransi Original'!C11*75%,4) -> 0.0264 | D11: =ROUNDUP('[1]Asuransi Original'!D11*75%,4) -> 0.0327 | E11: =ROUNDUP('[1]Asuransi Original'!E11*75%,4) -> 0.0499 | F11: =ROUNDUP('[1]Asuransi Original'!F11*75%,4) -> 0.0555 | G11: =ROUNDUP('[1]Asuransi Original'!G11*75%,4) -> 0.1617 | H11: =ROUNDUP('[1]Asuransi Original'!H11*75%,4) -> 0.1639 | I11: =ROUNDUP('[1]Asuransi Original'!I11*75%,4) -> 0.1729 | J11: =ROUNDUP('[1]Asuransi Original'!J11*75%,4) -> 0.1767 | ... L11: =ROUNDUP('[1]Asuransi Original'!L11*75%,4) -> 0.195 | M11: 0 | N11: 0 | O11: 0 | P11: 0 | Q11: 0 | R11: =IF(Ref!$Z$16<=$C$3,C11,IF(Ref!$Z$16<$D$3,C11,IF(Ref!$Z$16<$E$3,D11,IF(Ref!$Z$16<$F$3,E11,IF(Ref!$Z$16<$G$3,F11,IF(Ref!$Z$16<$H$3,G11,(IF(Ref!$Z$16<$I$3,H11,IF(Ref!$Z$16<$J$3,I11,IF(Ref!$Z$16<$K$3,J11,IF(Ref!$Z$16<$L$3,K11,IF(Ref!$Z$16<$M$3,L11,IF(Ref!$Z$16<$N$3,M11,IF(Ref!$Z$16<$O$3,N11,IF(Ref!$Z$16<$P$3,O11,IF(Ref!$Z$16<$Q$3,P11,IF(Ref!$Z$16<=$Q$3,Q11))))))))))))))))) -> 0.195 | V11: =IF(V10>V9,V10,V9) -> 0.255
B12: 72 | C12: =ROUNDUP('[1]Asuransi Original'!C12*75%,4) -> 0.0264 | D12: =ROUNDUP('[1]Asuransi Original'!D12*75%,4) -> 0.0327 | E12: =ROUNDUP('[1]Asuransi Original'!E12*75%,4) -> 0.0499 | F12: =ROUNDUP('[1]Asuransi Original'!F12*75%,4) -> 0.1388 | G12: =ROUNDUP('[1]Asuransi Original'!G12*75%,4) -> 0.1662 | H12: =ROUNDUP('[1]Asuransi Original'!H12*75%,4) -> 0.1684 | I12: =ROUNDUP('[1]Asuransi Original'!I12*75%,4) -> 0.1737 | J12: =ROUNDUP('[1]Asuransi Original'!J12*75%,4) -> 0.1774 | ... L12: =ROUNDUP('[1]Asuransi Original'!L12*75%,4) -> 0.21 | M12: 0 | N12: 0 | O12: 0 | P12: 0 | Q12: 0 | R12: =IF(Ref!$Z$16<=$C$3,C12,IF(Ref!$Z$16<$D$3,C12,IF(Ref!$Z$16<$E$3,D12,IF(Ref!$Z$16<$F$3,E12,IF(Ref!$Z$16<$G$3,F12,IF(Ref!$Z$16<$H$3,G12,(IF(Ref!$Z$16<$I$3,H12,IF(Ref!$Z$16<$J$3,I12,IF(Ref!$Z$16<$K$3,J12,IF(Ref!$Z$16<$L$3,K12,IF(Ref!$Z$16<$M$3,L12,IF(Ref!$Z$16<$N$3,M12,IF(Ref!$Z$16<$O$3,N12,IF(Ref!$Z$16<$P$3,O12,IF(Ref!$Z$16<$Q$3,P12,IF(Ref!$Z$16<=$Q$3,Q12))))))))))))))))) -> 0.21
B13: 73 | C13: =ROUNDUP('[1]Asuransi Original'!C13*75%,4) -> 0.0264 | D13: =ROUNDUP('[1]Asuransi Original'!D13*75%,4) -> 0.0327 | E13: =ROUNDUP('[1]Asuransi Original'!E13*75%,4) -> 0.1185 | F13: =ROUNDUP('[1]Asuransi Original'!F13*75%,4) -> 0.1482 | G13: =ROUNDUP('[1]Asuransi Original'!G13*75%,4) -> 0.1684 | H13: =ROUNDUP('[1]Asuransi Original'!H13*75%,4) -> 0.1707 | I13: =ROUNDUP('[1]Asuransi Original'!I13*75%,4) -> 0.1752 | J13: =ROUNDUP('[1]Asuransi Original'!J13*75%,4) -> 0.1875 | ... L13: =ROUNDUP('[1]Asuransi Original'!L13*75%,4) -> 0.225 | M13: 0 | N13: 0 | O13: 0 | P13: 0 | Q13: 0 | R13: =IF(Ref!$Z$16<=$C$3,C13,IF(Ref!$Z$16<$D$3,C13,IF(Ref!$Z$16<$E$3,D13,IF(Ref!$Z$16<$F$3,E13,IF(Ref!$Z$16<$G$3,F13,IF(Ref!$Z$16<$H$3,G13,(IF(Ref!$Z$16<$I$3,H13,IF(Ref!$Z$16<$J$3,I13,IF(Ref!$Z$16<$K$3,J13,IF(Ref!$Z$16<$L$3,K13,IF(Ref!$Z$16<$M$3,L13,IF(Ref!$Z$16<$N$3,M13,IF(Ref!$Z$16<$O$3,N13,IF(Ref!$Z$16<$P$3,O13,IF(Ref!$Z$16<$Q$3,P13,IF(Ref!$Z$16<=$Q$3,Q13))))))))))))))))) -> 0.225 | T13: =IF('Simulasi BPR'!I7<=65,65,AA7) -> 0
B14: 74 | C14: =ROUNDUP('[1]Asuransi Original'!C14*75%,4) -> 0.0264 | D14: =ROUNDUP('[1]Asuransi Original'!D14*75%,4) -> 0.0327 | E14: =ROUNDUP('[1]Asuransi Original'!E14*75%,4) -> 0.1215 | F14: =ROUNDUP('[1]Asuransi Original'!F14*75%,4) -> 0.1515 | G14: =ROUNDUP('[1]Asuransi Original'!G14*75%,4) -> 0.1684 | H14: =ROUNDUP('[1]Asuransi Original'!H14*75%,4) -> 0.1707 | I14: =ROUNDUP('[1]Asuransi Original'!I14*75%,4) -> 0.1875 | J14: =ROUNDUP('[1]Asuransi Original'!J14*75%,4) -> 0.195 | ... L14: =ROUNDUP('[1]Asuransi Original'!L14*75%,4) -> 0.24 | M14: 0 | N14: 0 | O14: 0 | P14: 0 | Q14: 0 | R14: =IF(Ref!$Z$16<=$C$3,C14,IF(Ref!$Z$16<$D$3,C14,IF(Ref!$Z$16<$E$3,D14,IF(Ref!$Z$16<$F$3,E14,IF(Ref!$Z$16<$G$3,F14,IF(Ref!$Z$16<$H$3,G14,(IF(Ref!$Z$16<$I$3,H14,IF(Ref!$Z$16<$J$3,I14,IF(Ref!$Z$16<$K$3,J14,IF(Ref!$Z$16<$L$3,K14,IF(Ref!$Z$16<$M$3,L14,IF(Ref!$Z$16<$N$3,M14,IF(Ref!$Z$16<$O$3,N14,IF(Ref!$Z$16<$P$3,O14,IF(Ref!$Z$16<$Q$3,P14,IF(Ref!$Z$16<=$Q$3,Q14))))))))))))))))) -> 0.24
B15: 75 | C15: =ROUNDUP('[1]Asuransi Original'!C15*75%,4) -> 0.0488 | D15: =ROUNDUP('[1]Asuransi Original'!D15*75%,4) -> 0.072 | E15: =ROUNDUP('[1]Asuransi Original'!E15*75%,4) -> 0.1253 | F15: =ROUNDUP('[1]Asuransi Original'!F15*75%,4) -> 0.1608 | G15: =ROUNDUP('[1]Asuransi Original'!G15*75%,4) -> 0.1707 | H15: =ROUNDUP('[1]Asuransi Original'!H15*75%,4) -> 0.1875 | I15: =ROUNDUP('[1]Asuransi Original'!I15*75%,4) -> 0.195 | J15: =ROUNDUP('[1]Asuransi Original'!J15*75%,4) -> 0.21 | ... L15: =ROUNDUP('[1]Asuransi Original'!L15*75%,4) -> 0.255 | M15: 0 | N15: 0 | O15: 0 | P15: 0 | Q15: 0 | R15: =IF(Ref!$Z$16<=$C$3,C15,IF(Ref!$Z$16<$D$3,C15,IF(Ref!$Z$16<$E$3,D15,IF(Ref!$Z$16<$F$3,E15,IF(Ref!$Z$16<$G$3,F15,IF(Ref!$Z$16<$H$3,G15,(IF(Ref!$Z$16<$I$3,H15,IF(Ref!$Z$16<$J$3,I15,IF(Ref!$Z$16<$K$3,J15,IF(Ref!$Z$16<$L$3,K15,IF(Ref!$Z$16<$M$3,L15,IF(Ref!$Z$16<$N$3,M15,IF(Ref!$Z$16<$O$3,N15,IF(Ref!$Z$16<$P$3,O15,IF(Ref!$Z$16<$Q$3,P15,IF(Ref!$Z$16<=$Q$3,Q15))))))))))))))))) -> 0.255
B16: 76 | C16: =ROUNDUP('[1]Asuransi Original'!C16*75%,4) -> 0.0488 | D16: =ROUNDUP('[1]Asuransi Original'!D16*75%,4) -> 0.0825 | E16: =ROUNDUP('[1]Asuransi Original'!E16*75%,4) -> 0.1253 | F16: =ROUNDUP('[1]Asuransi Original'!F16*75%,4) -> 0.1608 | G16: =ROUNDUP('[1]Asuransi Original'!G16*75%,4) -> 0.1875 | H16: =ROUNDUP('[1]Asuransi Original'!H16*75%,4) -> 0.195 | I16: =ROUNDUP('[1]Asuransi Original'!I16*75%,4) -> 0.21 | J16: =ROUNDUP('[1]Asuransi Original'!J16*75%,4) -> 0.2175 | K16: =ROUNDUP('[1]Asuransi Original'!K16*75%,4) -> 0.24 | L16: 0 | M16: 0 | N16: 0 | O16: 0 | P16: 0 | Q16: 0 | R16: =IF(Ref!$Z$16<=$C$3,C16,IF(Ref!$Z$16<$D$3,C16,IF(Ref!$Z$16<$E$3,D16,IF(Ref!$Z$16<$F$3,E16,IF(Ref!$Z$16<$G$3,F16,IF(Ref!$Z$16<$H$3,G16,(IF(Ref!$Z$16<$I$3,H16,IF(Ref!$Z$16<$J$3,I16,IF(Ref!$Z$16<$K$3,J16,IF(Ref!$Z$16<$L$3,K16,IF(Ref!$Z$16<$M$3,L16,IF(Ref!$Z$16<$N$3,M16,IF(Ref!$Z$16<$O$3,N16,IF(Ref!$Z$16<$P$3,O16,IF(Ref!$Z$16<$Q$3,P16,IF(Ref!$Z$16<=$Q$3,Q16))))))))))))))))) -> 0
B17: 77 | C17: =ROUNDUP('[1]Asuransi Original'!C17*75%,4) -> 0.0488 | D17: =ROUNDUP('[1]Asuransi Original'!D17*75%,4) -> 0.0825 | E17: =ROUNDUP('[1]Asuransi Original'!E17*75%,4) -> 0.1253 | F17: =ROUNDUP('[1]Asuransi Original'!F17*75%,4) -> 0.1875 | G17: =ROUNDUP('[1]Asuransi Original'!G17*75%,4) -> 0.195 | H17: =ROUNDUP('[1]Asuransi Original'!H17*75%,4) -> 0.21 | I17: =ROUNDUP('[1]Asuransi Original'!I17*75%,4) -> 0.2175 | J17: =ROUNDUP('[1]Asuransi Original'!J17*75%,4) -> 0.2325 | K17: 0 | L17: 0 | M17: 0 | N17: 0 | O17: 0 | P17: 0 | Q17: 0 | R17: =IF(Ref!$Z$16<=$C$3,C17,IF(Ref!$Z$16<$D$3,C17,IF(Ref!$Z$16<$E$3,D17,IF(Ref!$Z$16<$F$3,E17,IF(Ref!$Z$16<$G$3,F17,IF(Ref!$Z$16<$H$3,G17,(IF(Ref!$Z$16<$I$3,H17,IF(Ref!$Z$16<$J$3,I17,IF(Ref!$Z$16<$K$3,J17,IF(Ref!$Z$16<$L$3,K17,IF(Ref!$Z$16<$M$3,L17,IF(Ref!$Z$16<$N$3,M17,IF(Ref!$Z$16<$O$3,N17,IF(Ref!$Z$16<$P$3,O17,IF(Ref!$Z$16<$Q$3,P17,IF(Ref!$Z$16<=$Q$3,Q17))))))))))))))))) -> 0
B18: 78 | C18: =ROUNDUP('[1]Asuransi Original'!C18*75%,4) -> 0.0488 | D18: =ROUNDUP('[1]Asuransi Original'!D18*75%,4) -> 0.0825 | E18: =ROUNDUP('[1]Asuransi Original'!E18*75%,4) -> 0.1875 | F18: =ROUNDUP('[1]Asuransi Original'!F18*75%,4) -> 0.195 | G18: =ROUNDUP('[1]Asuransi Original'!G18*75%,4) -> 0.21 | H18: =ROUNDUP('[1]Asuransi Original'!H18*75%,4) -> 0.2175 | I18: =ROUNDUP('[1]Asuransi Original'!I18*75%,4) -> 0.225 | J18: 0 | K18: 0 | L18: 0 | M18: 0 | N18: 0 | O18: 0 | P18: 0 | Q18: 0 | R18: =IF(Ref!$Z$16<=$C$3,C18,IF(Ref!$Z$16<$D$3,C18,IF(Ref!$Z$16<$E$3,D18,IF(Ref!$Z$16<$F$3,E18,IF(Ref!$Z$16<$G$3,F18,IF(Ref!$Z$16<$H$3,G18,(IF(Ref!$Z$16<$I$3,H18,IF(Ref!$Z$16<$J$3,I18,IF(Ref!$Z$16<$K$3,J18,IF(Ref!$Z$16<$L$3,K18,IF(Ref!$Z$16<$M$3,L18,IF(Ref!$Z$16<$N$3,M18,IF(Ref!$Z$16<$O$3,N18,IF(Ref!$Z$16<$P$3,O18,IF(Ref!$Z$16<$Q$3,P18,IF(Ref!$Z$16<=$Q$3,Q18))))))))))))))))) -> 0
B19: 79 | C19: =ROUNDUP('[1]Asuransi Original'!C19*75%,4) -> 0.0488 | D19: =ROUNDUP('[1]Asuransi Original'!D19*75%,4) -> 0.105 | E19: =ROUNDUP('[1]Asuransi Original'!E19*75%,4) -> 0.195 | F19: =ROUNDUP('[1]Asuransi Original'!F19*75%,4) -> 0.21 | G19: =ROUNDUP('[1]Asuransi Original'!G19*75%,4) -> 0.2175 | H19: =ROUNDUP('[1]Asuransi Original'!H19*75%,4) -> 0.225 | I19: 0 | J19: 0 | K19: 0 | L19: 0 | M19: 0 | N19: 0 | O19: 0 | P19: 0 | Q19: 0 | R19: =IF(Ref!$Z$16<=$C$3,C19,IF(Ref!$Z$16<$D$3,C19,IF(Ref!$Z$16<$E$3,D19,IF(Ref!$Z$16<$F$3,E19,IF(Ref!$Z$16<$G$3,F19,IF(Ref!$Z$16<$H$3,G19,(IF(Ref!$Z$16<$I$3,H19,IF(Ref!$Z$16<$J$3,I19,IF(Ref!$Z$16<$K$3,J19,IF(Ref!$Z$16<$L$3,K19,IF(Ref!$Z$16<$M$3,L19,IF(Ref!$Z$16<$N$3,M19,IF(Ref!$Z$16<$O$3,N19,IF(Ref!$Z$16<$P$3,O19,IF(Ref!$Z$16<$Q$3,P19,IF(Ref!$Z$16<=$Q$3,Q19))))))))))))))))) -> 0
B20: 80 | C20: =ROUNDUP('[1]Asuransi Original'!C20*75%,4) -> 0.0803 | D20: =ROUNDUP('[1]Asuransi Original'!D20*75%,4) -> 0.12 | E20: =ROUNDUP('[1]Asuransi Original'!E20*75%,4) -> 0.21 | F20: =ROUNDUP('[1]Asuransi Original'!F20*75%,4) -> 0.2175 | G20: =ROUNDUP('[1]Asuransi Original'!G20*75%,4) -> 0.225 | H20: 0 | I20: 0 | J20: 0 | K20: 0 | L20: 0 | M20: 0 | N20: 0 | O20: 0 | P20: 0 | Q20: 0 | R20: =IF(Ref!$Z$16<=$C$3,C20,IF(Ref!$Z$16<$D$3,C20,IF(Ref!$Z$16<$E$3,D20,IF(Ref!$Z$16<$F$3,E20,IF(Ref!$Z$16<$G$3,F20,IF(Ref!$Z$16<$H$3,G20,(IF(Ref!$Z$16<$I$3,H20,IF(Ref!$Z$16<$J$3,I20,IF(Ref!$Z$16<$K$3,J20,IF(Ref!$Z$16<$L$3,K20,IF(Ref!$Z$16<$M$3,L20,IF(Ref!$Z$16<$N$3,M20,IF(Ref!$Z$16<$O$3,N20,IF(Ref!$Z$16<$P$3,O20,IF(Ref!$Z$16<$Q$3,P20,IF(Ref!$Z$16<=$Q$3,Q20))))))))))))))))) -> 0
B21: 81 | C21: =ROUNDUP('[1]Asuransi Original'!C21*75%,4) -> 0.0927 | D21: =ROUNDUP('[1]Asuransi Original'!D21*75%,4) -> 0.135 | E21: =ROUNDUP('[1]Asuransi Original'!E21*75%,4) -> 0.2175 | F21: =ROUNDUP('[1]Asuransi Original'!F21*75%,4) -> 0.225 | G21: 0 | H21: 0 | I21: 0 | J21: 0 | K21: 0 | L21: 0 | M21: 0 | N21: 0 | O21: 0 | P21: 0 | Q21: 0 | R21: =IF(Ref!$Z$16<=$C$3,C21,IF(Ref!$Z$16<$D$3,C21,IF(Ref!$Z$16<$E$3,D21,IF(Ref!$Z$16<$F$3,E21,IF(Ref!$Z$16<$G$3,F21,IF(Ref!$Z$16<$H$3,G21,(IF(Ref!$Z$16<$I$3,H21,IF(Ref!$Z$16<$J$3,I21,IF(Ref!$Z$16<$K$3,J21,IF(Ref!$Z$16<$L$3,K21,IF(Ref!$Z$16<$M$3,L21,IF(Ref!$Z$16<$N$3,M21,IF(Ref!$Z$16<$O$3,N21,IF(Ref!$Z$16<$P$3,O21,IF(Ref!$Z$16<$Q$3,P21,IF(Ref!$Z$16<=$Q$3,Q21))))))))))))))))) -> 0
B22: 82 | C22: =ROUNDUP('[1]Asuransi Original'!C22*75%,4) -> 0.1107 | D22: =ROUNDUP('[1]Asuransi Original'!D22*75%,4) -> 0.165 | E22: =ROUNDUP('[1]Asuransi Original'!E22*75%,4) -> 0.225 | F22: 0 | G22: 0 | H22: 0 | I22: 0 | J22: 0 | K22: 0 | L22: 0 | M22: 0 | N22: 0 | O22: 0 | P22: 0 | Q22: 0 | R22: =IF(Ref!$Z$16<=$C$3,C22,IF(Ref!$Z$16<$D$3,C22,IF(Ref!$Z$16<$E$3,D22,IF(Ref!$Z$16<$F$3,E22,IF(Ref!$Z$16<$G$3,F22,IF(Ref!$Z$16<$H$3,G22,(IF(Ref!$Z$16<$I$3,H22,IF(Ref!$Z$16<$J$3,I22,IF(Ref!$Z$16<$K$3,J22,IF(Ref!$Z$16<$L$3,K22,IF(Ref!$Z$16<$M$3,L22,IF(Ref!$Z$16<$N$3,M22,IF(Ref!$Z$16<$O$3,N22,IF(Ref!$Z$16<$P$3,O22,IF(Ref!$Z$16<$Q$3,P22,IF(Ref!$Z$16<=$Q$3,Q22))))))))))))))))) -> 0
B23: 83 | C23: =ROUNDUP('[1]Asuransi Original'!C23*75%,4) -> 0.1253 | D23: =ROUNDUP('[1]Asuransi Original'!D23*75%,4) -> 0.18 | E23: 0 | F23: 0 | G23: 0 | H23: 0 | I23: 0 | J23: 0 | K23: 0 | L23: 0 | M23: 0 | N23: 0 | O23: 0 | P23: 0 | Q23: 0 | R23: =IF(Ref!$Z$16<=$C$3,C23,IF(Ref!$Z$16<$D$3,C23,IF(Ref!$Z$16<$E$3,D23,IF(Ref!$Z$16<$F$3,E23,IF(Ref!$Z$16<$G$3,F23,IF(Ref!$Z$16<$H$3,G23,(IF(Ref!$Z$16<$I$3,H23,IF(Ref!$Z$16<$J$3,I23,IF(Ref!$Z$16<$K$3,J23,IF(Ref!$Z$16<$L$3,K23,IF(Ref!$Z$16<$M$3,L23,IF(Ref!$Z$16<$N$3,M23,IF(Ref!$Z$16<$O$3,N23,IF(Ref!$Z$16<$P$3,O23,IF(Ref!$Z$16<$Q$3,P23,IF(Ref!$Z$16<=$Q$3,Q23))))))))))))))))) -> 0
B24: 84 | C24: =ROUNDUP('[1]Asuransi Original'!C24*75%,4) -> 0.1369 | D24: 0 | E24: 0 | F24: 0 | G24: 0 | H24: 0 | I24: 0 | J24: 0 | K24: 0 | L24: 0 | M24: 0 | N24: 0 | O24: 0 | P24: 0 | Q24: 0 | R24: =IF(Ref!$Z$16<=$C$3,C24,IF(Ref!$Z$16<$D$3,C24,IF(Ref!$Z$16<$E$3,D24,IF(Ref!$Z$16<$F$3,E24,IF(Ref!$Z$16<$G$3,F24,IF(Ref!$Z$16<$H$3,G24,(IF(Ref!$Z$16<$I$3,H24,IF(Ref!$Z$16<$J$3,I24,IF(Ref!$Z$16<$K$3,J24,IF(Ref!$Z$16<$L$3,K24,IF(Ref!$Z$16<$M$3,L24,IF(Ref!$Z$16<$N$3,M24,IF(Ref!$Z$16<$O$3,N24,IF(Ref!$Z$16<$P$3,O24,IF(Ref!$Z$16<$Q$3,P24,IF(Ref!$Z$16<=$Q$3,Q24))))))))))))))))) -> 0
B26: USIA | J26: TENOR
B27: MASUK | C27: 1 | D27: 2 | E27: 3 | F27: 4 | G27: 5 | H27: 6 | I27: 7 | J27: 8 | K27: 9 | L27: 10 | M27: 11 | N27: 12 | O27: 13 | P27: 14 | Q27: 15 | R27: =IF(Ref!$Z$4<=B29,R29,IF(Ref!$Z$4=B30,R30,IF(Ref!$Z$4=B31,R31,IF(Ref!$Z$4=B32,R32,IF(Ref!$Z$4=B33,R33,IF(Ref!$Z$4=B34,R34,IF(Ref!$Z$4=B35,R35,IF(Ref!$Z$4=B36,R36,IF(Ref!$Z$4=B37,R37,IF(Ref!$Z$4=B38,R38,IF(Ref!$Z$4=B39,R39,IF(Ref!$Z$4=B40,R40,IF(Ref!$Z$4=B41,R41,IF(Ref!$Z$4=B42,R42,IF(Ref!$Z$4=B43,R43,IF(Ref!$Z$4=B44,R44,IF(Ref!$Z$4=B45,R45,IF(Ref!$Z$4=B46,R46,IF(Ref!$Z$4=B47,R47,IF(Ref!$Z$4=B48,R48,IF(Ref!$Z$4<80,R48))))))))))))))))))))) -> 0.265 | T27: 12 | U27: 24 | V27: 36 | W27: 48 | X27: 60 | Y27: 72 | Z27: 84 | AA27: 96 | AB27: 108 | AC27: 120
B29: 65 | C29: =C5+1% -> 0.0149 | D29: =D5+1% -> 0.0198 | E29: =E5+1% -> 0.0247 | F29: =F5+1% -> 0.0295 | G29: =G5+1% -> 0.0344 | H29: =H5+1% -> 0.0608 | I29: =I5+1% -> 0.0715 | J29: =J5+1% -> 0.0843 | ... Q29: =Q5+1% -> 0.202 | R29: =IF(Ref!$Z$16<=$C$3,C29,IF(Ref!$Z$16<$D$3,C29,IF(Ref!$Z$16<$E$3,D29,IF(Ref!$Z$16<$F$3,E29,IF(Ref!$Z$16<$G$3,F29,IF(Ref!$Z$16<$H$3,G29,(IF(Ref!$Z$16<$I$3,H29,IF(Ref!$Z$16<$J$3,I29,IF(Ref!$Z$16<$K$3,J29,IF(Ref!$Z$16<$L$3,K29,IF(Ref!$Z$16<$M$3,L29,IF(Ref!$Z$16<$N$3,M29,IF(Ref!$Z$16<$O$3,N29,IF(Ref!$Z$16<$P$3,O29,IF(Ref!$Z$16<$Q$3,P29,IF(Ref!$Z$16<=$Q$3,Q29))))))))))))))))) -> 0.1023 | S29: 70 - 74 | T29: 0.06069 | U29: 0.09136 | V29: 0.12993 | W29: 0.16079 | X29: 0.19357 | Y29: 0.22025 | Z29: 0.24371 | AA29: 0.26686 | AB29: 0.28807 | AC29: 0.29932
B30: 66 | C30: =C6+1% -> 0.0149 | D30: =D6+1% -> 0.0198 | E30: =E6+1% -> 0.0247 | F30: =F6+1% -> 0.0295 | G30: =G6+1% -> 0.0559 | H30: =H6+1% -> 0.0667 | I30: =I6+1% -> 0.0794 | J30: =J6+1% -> 0.085 | ... P30: =P6+1% -> 0.2002 | Q30: 0 | R30: =IF(Ref!$Z$16<=$C$3,C30,IF(Ref!$Z$16<$D$3,C30,IF(Ref!$Z$16<$E$3,D30,IF(Ref!$Z$16<$F$3,E30,IF(Ref!$Z$16<$G$3,F30,IF(Ref!$Z$16<$H$3,G30,(IF(Ref!$Z$16<$I$3,H30,IF(Ref!$Z$16<$J$3,I30,IF(Ref!$Z$16<$K$3,J30,IF(Ref!$Z$16<$L$3,K30,IF(Ref!$Z$16<$M$3,L30,IF(Ref!$Z$16<$N$3,M30,IF(Ref!$Z$16<$O$3,N30,IF(Ref!$Z$16<$P$3,O30,IF(Ref!$Z$16<$Q$3,P30,IF(Ref!$Z$16<=$Q$3,Q30))))))))))))))))) -> 0.1762 | T30: 0.065 | U30: 0.11 | V30: 0.15179 | W30: 0.195 | X30: 0.23921 | Y30: 0 | Z30: 0 | AA30: 0 | AB30: 0 | AC30: 0
B31: 67 | C31: =C7+1% -> 0.0149 | D31: =D7+1% -> 0.0198 | E31: =E7+1% -> 0.0247 | F31: =F7+1% -> 0.0511 | G31: =G7+1% -> 0.0618 | H31: =H7+1% -> 0.0745 | I31: =I7+1% -> 0.0802 | J31: =J7+1% -> 0.0925 | ... O31: =O7+1% -> 0.1912 | P31: 0 | Q31: 0 | R31: =IF(Ref!$Z$16<=$C$3,C31,IF(Ref!$Z$16<$D$3,C31,IF(Ref!$Z$16<$E$3,D31,IF(Ref!$Z$16<$F$3,E31,IF(Ref!$Z$16<$G$3,F31,IF(Ref!$Z$16<$H$3,G31,(IF(Ref!$Z$16<$I$3,H31,IF(Ref!$Z$16<$J$3,I31,IF(Ref!$Z$16<$K$3,J31,IF(Ref!$Z$16<$L$3,K31,IF(Ref!$Z$16<$M$3,L31,IF(Ref!$Z$16<$N$3,M31,IF(Ref!$Z$16<$O$3,N31,IF(Ref!$Z$16<$P$3,O31,IF(Ref!$Z$16<$Q$3,P31,IF(Ref!$Z$16<=$Q$3,Q31))))))))))))))))) -> 0.1837 | T31: 75-79 | U31: 75-78 | V31: 75-77 | W31: 75-76 | X31: 75-75
B32: 68 | C32: =C8+1% -> 0.0149 | D32: =D8+1% -> 0.0198 | E32: =E8+1% -> 0.0462 | F32: =F8+1% -> 0.0569 | G32: =G8+1% -> 0.0697 | H32: =H8+1% -> 0.0753 | I32: =I8+1% -> 0.0877 | J32: =J8+1% -> 0.1762 | ... N32: =N8+1% -> 0.1987 | O32: 0 | P32: 0 | Q32: 0 | R32: =IF(Ref!$Z$16<=$C$3,C32,IF(Ref!$Z$16<$D$3,C32,IF(Ref!$Z$16<$E$3,D32,IF(Ref!$Z$16<$F$3,E32,IF(Ref!$Z$16<$G$3,F32,IF(Ref!$Z$16<$H$3,G32,(IF(Ref!$Z$16<$I$3,H32,IF(Ref!$Z$16<$J$3,I32,IF(Ref!$Z$16<$K$3,J32,IF(Ref!$Z$16<$L$3,K32,IF(Ref!$Z$16<$M$3,L32,IF(Ref!$Z$16<$N$3,M32,IF(Ref!$Z$16<$O$3,N32,IF(Ref!$Z$16<$P$3,O32,IF(Ref!$Z$16<$Q$3,P32,IF(Ref!$Z$16<=$Q$3,Q32))))))))))))))))) -> 0.1874
B33: 69 | C33: =C9+1% -> 0.0149 | D33: =D9+1% -> 0.0413 | E33: =E9+1% -> 0.052 | F33: =F9+1% -> 0.0648 | G33: =G9+1% -> 0.0704 | H33: =H9+1% -> 0.0828 | I33: =I9+1% -> 0.1792 | J33: =J9+1% -> 0.1837 | ... M33: =M9+1% -> 0.1964 | N33: 0 | O33: 0 | P33: 0 | Q33: 0 | R33: =IF(Ref!$Z$16<=$C$3,C33,IF(Ref!$Z$16<$D$3,C33,IF(Ref!$Z$16<$E$3,D33,IF(Ref!$Z$16<$F$3,E33,IF(Ref!$Z$16<$G$3,F33,IF(Ref!$Z$16<$H$3,G33,(IF(Ref!$Z$16<$I$3,H33,IF(Ref!$Z$16<$J$3,I33,IF(Ref!$Z$16<$K$3,J33,IF(Ref!$Z$16<$L$3,K33,IF(Ref!$Z$16<$M$3,L33,IF(Ref!$Z$16<$N$3,M33,IF(Ref!$Z$16<$O$3,N33,IF(Ref!$Z$16<$P$3,O33,IF(Ref!$Z$16<$Q$3,P33,IF(Ref!$Z$16<=$Q$3,Q33))))))))))))))))) -> 0.1912 | S33: AA7 | T33: =IF('Simulasi BPR'!$I$7<=65,65,'Simulasi BPR'!I$7) -> 74 | U33: =Ref!$Z$16 -> 10 | V33: =INDEX($C$29:$Q$48,MATCH($T33,$B$29:$B$48,0),MATCH($U33,$C$27:$Q$27,0)) -> 0.25
B34: 70 | C34: =C10+1% -> 0.0364 | D34: =D10+1% -> 0.0427 | E34: =E10+1% -> 0.0599 | F34: =F10+1% -> 0.0655 | G34: =G10+1% -> 0.0779 | H34: =H10+1% -> 0.1717 | I34: =I10+1% -> 0.1814 | J34: =J10+1% -> 0.1859 | ... L34: =L10+1% -> 0.1934 | M34: 0 | N34: 0 | O34: 0 | P34: 0 | Q34: 0 | R34: =IF(Ref!$Z$16<=$C$3,C34,IF(Ref!$Z$16<$D$3,C34,IF(Ref!$Z$16<$E$3,D34,IF(Ref!$Z$16<$F$3,E34,IF(Ref!$Z$16<$G$3,F34,IF(Ref!$Z$16<$H$3,G34,(IF(Ref!$Z$16<$I$3,H34,IF(Ref!$Z$16<$J$3,I34,IF(Ref!$Z$16<$K$3,J34,IF(Ref!$Z$16<$L$3,K34,IF(Ref!$Z$16<$M$3,L34,IF(Ref!$Z$16<$N$3,M34,IF(Ref!$Z$16<$O$3,N34,IF(Ref!$Z$16<$P$3,O34,IF(Ref!$Z$16<$Q$3,P34,IF(Ref!$Z$16<=$Q$3,Q34))))))))))))))))) -> 0.1934 | S34: AA7+1 | T34: =T33+1 -> 75 | U34: =Ref!$Z$16 -> 10 | V34: =INDEX($C$29:$Q$48,MATCH($T34,$B$29:$B$48,0),MATCH($U34,$C$27:$Q$27,0)) -> 0.265
B35: 71 | C35: =C11+1% -> 0.0364 | D35: =D11+1% -> 0.0427 | E35: =E11+1% -> 0.0599 | F35: =F11+1% -> 0.0655 | G35: =G11+1% -> 0.1717 | H35: =H11+1% -> 0.1739 | I35: =I11+1% -> 0.1829 | J35: =J11+1% -> 0.1867 | ... L35: =L11+1% -> 0.205 | M35: 0 | N35: 0 | O35: 0 | P35: 0 | Q35: 0 | R35: =IF(Ref!$Z$16<=$C$3,C35,IF(Ref!$Z$16<$D$3,C35,IF(Ref!$Z$16<$E$3,D35,IF(Ref!$Z$16<$F$3,E35,IF(Ref!$Z$16<$G$3,F35,IF(Ref!$Z$16<$H$3,G35,(IF(Ref!$Z$16<$I$3,H35,IF(Ref!$Z$16<$J$3,I35,IF(Ref!$Z$16<$K$3,J35,IF(Ref!$Z$16<$L$3,K35,IF(Ref!$Z$16<$M$3,L35,IF(Ref!$Z$16<$N$3,M35,IF(Ref!$Z$16<$O$3,N35,IF(Ref!$Z$16<$P$3,O35,IF(Ref!$Z$16<$Q$3,P35,IF(Ref!$Z$16<=$Q$3,Q35))))))))))))))))) -> 0.205 | V35: =IF(V34>V33,V34,V33) -> 0.265
B36: 72 | C36: =C12+1% -> 0.0364 | D36: =D12+1% -> 0.0427 | E36: =E12+1% -> 0.0599 | F36: =F12+1% -> 0.1488 | G36: =G12+1% -> 0.1762 | H36: =H12+1% -> 0.1784 | I36: =I12+1% -> 0.1837 | J36: =J12+1% -> 0.1874 | ... L36: =L12+1% -> 0.22 | M36: 0 | N36: 0 | O36: 0 | P36: 0 | Q36: 0 | R36: =IF(Ref!$Z$16<=$C$3,C36,IF(Ref!$Z$16<$D$3,C36,IF(Ref!$Z$16<$E$3,D36,IF(Ref!$Z$16<$F$3,E36,IF(Ref!$Z$16<$G$3,F36,IF(Ref!$Z$16<$H$3,G36,(IF(Ref!$Z$16<$I$3,H36,IF(Ref!$Z$16<$J$3,I36,IF(Ref!$Z$16<$K$3,J36,IF(Ref!$Z$16<$L$3,K36,IF(Ref!$Z$16<$M$3,L36,IF(Ref!$Z$16<$N$3,M36,IF(Ref!$Z$16<$O$3,N36,IF(Ref!$Z$16<$P$3,O36,IF(Ref!$Z$16<$Q$3,P36,IF(Ref!$Z$16<=$Q$3,Q36))))))))))))))))) -> 0.22
B37: 73 | C37: =C13+1% -> 0.0364 | D37: =D13+1% -> 0.0427 | E37: =E13+1% -> 0.1285 | F37: =F13+1% -> 0.1582 | G37: =G13+1% -> 0.1784 | H37: =H13+1% -> 0.1807 | I37: =I13+1% -> 0.1852 | J37: =J13+1% -> 0.1975 | ... L37: =L13+1% -> 0.235 | M37: 0 | N37: 0 | O37: 0 | P37: 0 | Q37: 0 | R37: =IF(Ref!$Z$16<=$C$3,C37,IF(Ref!$Z$16<$D$3,C37,IF(Ref!$Z$16<$E$3,D37,IF(Ref!$Z$16<$F$3,E37,IF(Ref!$Z$16<$G$3,F37,IF(Ref!$Z$16<$H$3,G37,(IF(Ref!$Z$16<$I$3,H37,IF(Ref!$Z$16<$J$3,I37,IF(Ref!$Z$16<$K$3,J37,IF(Ref!$Z$16<$L$3,K37,IF(Ref!$Z$16<$M$3,L37,IF(Ref!$Z$16<$N$3,M37,IF(Ref!$Z$16<$O$3,N37,IF(Ref!$Z$16<$P$3,O37,IF(Ref!$Z$16<$Q$3,P37,IF(Ref!$Z$16<=$Q$3,Q37))))))))))))))))) -> 0.235 | T37: =IF('Simulasi BPR'!I31<=65,65,AA31) -> 65
B38: 74 | C38: =C14+1% -> 0.0364 | D38: =D14+1% -> 0.0427 | E38: =E14+1% -> 0.1315 | F38: =F14+1% -> 0.1615 | G38: =G14+1% -> 0.1784 | H38: =H14+1% -> 0.1807 | I38: =I14+1% -> 0.1975 | J38: =J14+1% -> 0.205 | ... L38: =L14+1% -> 0.25 | M38: 0 | N38: 0 | O38: 0 | P38: 0 | Q38: 0 | R38: =IF(Ref!$Z$16<=$C$3,C38,IF(Ref!$Z$16<$D$3,C38,IF(Ref!$Z$16<$E$3,D38,IF(Ref!$Z$16<$F$3,E38,IF(Ref!$Z$16<$G$3,F38,IF(Ref!$Z$16<$H$3,G38,(IF(Ref!$Z$16<$I$3,H38,IF(Ref!$Z$16<$J$3,I38,IF(Ref!$Z$16<$K$3,J38,IF(Ref!$Z$16<$L$3,K38,IF(Ref!$Z$16<$M$3,L38,IF(Ref!$Z$16<$N$3,M38,IF(Ref!$Z$16<$O$3,N38,IF(Ref!$Z$16<$P$3,O38,IF(Ref!$Z$16<$Q$3,P38,IF(Ref!$Z$16<=$Q$3,Q38))))))))))))))))) -> 0.25
B39: 75 | C39: =C15+1% -> 0.0588 | D39: =D15+1% -> 0.082 | E39: =E15+1% -> 0.1353 | F39: =F15+1% -> 0.1708 | G39: =G15+1% -> 0.1807 | H39: =H15+1% -> 0.1975 | I39: =I15+1% -> 0.205 | J39: =J15+1% -> 0.22 | ... L39: =L15+1% -> 0.265 | M39: 0 | N39: 0 | O39: 0 | P39: 0 | Q39: 0 | R39: =IF(Ref!$Z$16<=$C$3,C39,IF(Ref!$Z$16<$D$3,C39,IF(Ref!$Z$16<$E$3,D39,IF(Ref!$Z$16<$F$3,E39,IF(Ref!$Z$16<$G$3,F39,IF(Ref!$Z$16<$H$3,G39,(IF(Ref!$Z$16<$I$3,H39,IF(Ref!$Z$16<$J$3,I39,IF(Ref!$Z$16<$K$3,J39,IF(Ref!$Z$16<$L$3,K39,IF(Ref!$Z$16<$M$3,L39,IF(Ref!$Z$16<$N$3,M39,IF(Ref!$Z$16<$O$3,N39,IF(Ref!$Z$16<$P$3,O39,IF(Ref!$Z$16<$Q$3,P39,IF(Ref!$Z$16<=$Q$3,Q39))))))))))))))))) -> 0.265
B40: 76 | C40: =C16+1% -> 0.0588 | D40: =D16+1% -> 0.0925 | E40: =E16+1% -> 0.1353 | F40: =F16+1% -> 0.1708 | G40: =G16+1% -> 0.1975 | H40: =H16+1% -> 0.205 | I40: =I16+1% -> 0.22 | J40: =J16+1% -> 0.2275 | K40: =K16+1% -> 0.25 | L40: 0 | M40: 0 | N40: 0 | O40: 0 | P40: 0 | Q40: 0 | R40: =IF(Ref!$Z$16<=$C$3,C40,IF(Ref!$Z$16<$D$3,C40,IF(Ref!$Z$16<$E$3,D40,IF(Ref!$Z$16<$F$3,E40,IF(Ref!$Z$16<$G$3,F40,IF(Ref!$Z$16<$H$3,G40,(IF(Ref!$Z$16<$I$3,H40,IF(Ref!$Z$16<$J$3,I40,IF(Ref!$Z$16<$K$3,J40,IF(Ref!$Z$16<$L$3,K40,IF(Ref!$Z$16<$M$3,L40,IF(Ref!$Z$16<$N$3,M40,IF(Ref!$Z$16<$O$3,N40,IF(Ref!$Z$16<$P$3,O40,IF(Ref!$Z$16<$Q$3,P40,IF(Ref!$Z$16<=$Q$3,Q40))))))))))))))))) -> 0
B41: 77 | C41: =C17+1% -> 0.0588 | D41: =D17+1% -> 0.0925 | E41: =E17+1% -> 0.1353 | F41: =F17+1% -> 0.1975 | G41: =G17+1% -> 0.205 | H41: =H17+1% -> 0.22 | I41: =I17+1% -> 0.2275 | J41: =J17+1% -> 0.2425 | K41: 0 | L41: 0 | M41: 0 | N41: 0 | O41: 0 | P41: 0 | Q41: 0 | R41: =IF(Ref!$Z$16<=$C$3,C41,IF(Ref!$Z$16<$D$3,C41,IF(Ref!$Z$16<$E$3,D41,IF(Ref!$Z$16<$F$3,E41,IF(Ref!$Z$16<$G$3,F41,IF(Ref!$Z$16<$H$3,G41,(IF(Ref!$Z$16<$I$3,H41,IF(Ref!$Z$16<$J$3,I41,IF(Ref!$Z$16<$K$3,J41,IF(Ref!$Z$16<$L$3,K41,IF(Ref!$Z$16<$M$3,L41,IF(Ref!$Z$16<$N$3,M41,IF(Ref!$Z$16<$O$3,N41,IF(Ref!$Z$16<$P$3,O41,IF(Ref!$Z$16<$Q$3,P41,IF(Ref!$Z$16<=$Q$3,Q41))))))))))))))))) -> 0
B42: 78 | C42: =C18+1% -> 0.0588 | D42: =D18+1% -> 0.0925 | E42: =E18+1% -> 0.1975 | F42: =F18+1% -> 0.205 | G42: =G18+1% -> 0.22 | H42: =H18+1% -> 0.2275 | I42: =I18+1% -> 0.235 | J42: 0 | K42: 0 | L42: 0 | M42: 0 | N42: 0 | O42: 0 | P42: 0 | Q42: 0 | R42: =IF(Ref!$Z$16<=$C$3,C42,IF(Ref!$Z$16<$D$3,C42,IF(Ref!$Z$16<$E$3,D42,IF(Ref!$Z$16<$F$3,E42,IF(Ref!$Z$16<$G$3,F42,IF(Ref!$Z$16<$H$3,G42,(IF(Ref!$Z$16<$I$3,H42,IF(Ref!$Z$16<$J$3,I42,IF(Ref!$Z$16<$K$3,J42,IF(Ref!$Z$16<$L$3,K42,IF(Ref!$Z$16<$M$3,L42,IF(Ref!$Z$16<$N$3,M42,IF(Ref!$Z$16<$O$3,N42,IF(Ref!$Z$16<$P$3,O42,IF(Ref!$Z$16<$Q$3,P42,IF(Ref!$Z$16<=$Q$3,Q42))))))))))))))))) -> 0
B43: 79 | C43: =C19+1% -> 0.0588 | D43: =D19+1% -> 0.115 | E43: =E19+1% -> 0.205 | F43: =F19+1% -> 0.22 | G43: =G19+1% -> 0.2275 | H43: =H19+1% -> 0.235 | I43: 0 | J43: 0 | K43: 0 | L43: 0 | M43: 0 | N43: 0 | O43: 0 | P43: 0 | Q43: 0 | R43: =IF(Ref!$Z$16<=$C$3,C43,IF(Ref!$Z$16<$D$3,C43,IF(Ref!$Z$16<$E$3,D43,IF(Ref!$Z$16<$F$3,E43,IF(Ref!$Z$16<$G$3,F43,IF(Ref!$Z$16<$H$3,G43,(IF(Ref!$Z$16<$I$3,H43,IF(Ref!$Z$16<$J$3,I43,IF(Ref!$Z$16<$K$3,J43,IF(Ref!$Z$16<$L$3,K43,IF(Ref!$Z$16<$M$3,L43,IF(Ref!$Z$16<$N$3,M43,IF(Ref!$Z$16<$O$3,N43,IF(Ref!$Z$16<$P$3,O43,IF(Ref!$Z$16<$Q$3,P43,IF(Ref!$Z$16<=$Q$3,Q43))))))))))))))))) -> 0
B44: 80 | C44: =C20+1% -> 0.0903 | D44: =D20+1% -> 0.13 | E44: =E20+1% -> 0.22 | F44: =F20+1% -> 0.2275 | G44: =G20+1% -> 0.235 | H44: 0 | I44: 0 | J44: 0 | K44: 0 | L44: 0 | M44: 0 | N44: 0 | O44: 0 | P44: 0 | Q44: 0 | R44: =IF(Ref!$Z$16<=$C$3,C44,IF(Ref!$Z$16<$D$3,C44,IF(Ref!$Z$16<$E$3,D44,IF(Ref!$Z$16<$F$3,E44,IF(Ref!$Z$16<$G$3,F44,IF(Ref!$Z$16<$H$3,G44,(IF(Ref!$Z$16<$I$3,H44,IF(Ref!$Z$16<$J$3,I44,IF(Ref!$Z$16<$K$3,J44,IF(Ref!$Z$16<$L$3,K44,IF(Ref!$Z$16<$M$3,L44,IF(Ref!$Z$16<$N$3,M44,IF(Ref!$Z$16<$O$3,N44,IF(Ref!$Z$16<$P$3,O44,IF(Ref!$Z$16<$Q$3,P44,IF(Ref!$Z$16<=$Q$3,Q44))))))))))))))))) -> 0
...

Sheet Simulasi BPR
A2: ISI DATA DENGAN LENGKAP | E2: ANALISA PERHITUNGAN
A3: PASTIKAN PENGISIAN SESUAI DATA PENGAJUAN | E3: =C7&" - "&C6 -> BPR Kota Madiun - PLATINUM
A4: Versi:1.0.19 | E4: TL : | F4: 100
A5: FRONTING | B5: : | C5: CENTRAL GLOBAL SOLUTION | E5: KELAHIRAN | I5: USIA SAAT INI | M5: USIA SAAT LUNAS
A6: JENIS PRODUK | B6: : | C6: PLATINUM | E6: Tgl | F6: Bulan | G6: Tahun | I6: Tahun | J6: Bulan | K6: Hari | M6: Tahun : Bulan : Hari
A7: SUMBER DANA | B7: : | C7: BPR Kota Madiun | E7: 19 | F7: 3 | G7: 1952 | I7: =DATEDIF(Ref!Z2,TODAY(),"y") -> 74 | J7: =DATEDIF(Ref!Z2,TODAY(),"ym") -> 5 | K7: =DATEDIF(Ref!Z2,TODAY(),"md") -> 5 | M7: =DATEDIF(Ref!Z2,N9,"Y")&" : "&DATEDIF(Ref!Z2,N9,"YM")&" : "&DATEDIF(Ref!Z2,N9,"MD") -> 84 : 5 : 5
A8: LAYANAN KPRK POS | B8: : | C8: SIDOARJO
A9: JUMLAH KPC | B9: : | C9: =VLOOKUP(C8,Ref!V2:W37,2,0)&" Kantor Pos Cabang" -> 17 Kantor Pos Cabang | E9: GAJI BERSIH | I9: MARGIN | J9: MAKSIMAL PLAFOND | M9: LUNAS : | N9: =EDATE(Ref!Y5,G13) -> 49911
A10: NAMA DEBITUR (KTP) | B10: : | C10: ST AISYAH | E10: Rp | F10: 1750000 | I10: =IF(C7="BPR Kota Madiun",Ref!C3,IF(C7="BPRS Bhakti Sumekar",Ref!C4,"")) -> 0.009 | J10: =Ref!AC18 -> 90800000 | M10: =Ref!Y10 -> OK | N10: ANALISA PERHITUNGAN
A11: NOPEN | B11: :
A12: STATUS PEMBIAYAAN | B12: : | C12: SK TANGAN | F12: Maksimal Tenor | G12: =Ref!AC10&" Bulan" -> 120 Bulan | I12: PLAFON PENGAJUAN | M12: Ratio | N12: Angsuran per-Bulan
A13: PELUNASAN KE | B13: : | F13: Tenor Pengajuan | G13: 120 | I13: Rp | J13: 90800000 | M13: =N13/F10 -> 0.89935238 | N13: =P13 -> 1573866.7 | P13: =(J13/G13)+(J13*10.8%)/12 -> 1573866.7
A15: ASAL KANTOR BAYAR | B15: : | C15: POS | E15: BIAYA & TITIPAN | I15: Angka PELUNASAN | M15: Ratio | N15: SISA GAJI per-Bulan
A16: JENIS PENSIUN | B16: : | C16: TASPEN | I16: Rp | J16: 12250000 | M16: =IF(N16="DIBAWAH 100 RB",0,N16/F10) -> 0.10064762 | N16: =F10-N13 -> 176133.33
A17: BIAYA FLAGGING | B17: : | C17: =615000 -> 615000 | E17: Admin | F17: =IF(AND(C$7="BPR Kota Madiun",C$18="POS"),Ref!E4,Ref!E3) -> 0.005 | G17: =F17*$J$13 -> 454000
A18: TUJUAN KANTOR BAYAR | B18: : | C18: MANTAP | E18: Provisi | F18: =IF(AND(C$7="BPR Kota Madiun",C$18="POS"),Ref!F4,Ref!F3) -> 0.005 | G18: =F18*$J$13 -> 454000
E19: Asuransi | F19: =Ref!H3 -> 0.315 | G19: =F19*J13 -> 28602000
F20: Verifikasi | G20: 1500000 | I20: TERIMA BERSIH
A21: NO KTP | B21: : | E21: Pot. Angsuran | F21: 1 | G21: =N13*F21 -> 1573866.7 | I21: Rp | J21: =J13-SUM(G16:G21)-J16-C17 -> 45351133 | N21: Isi Kolom "WARNA HIJAU"
A22: calculated by CGS | E22: No.Tlp :
E23: VERSI 20260629 - UMUM
A24: No Rek | B24: : | E24: Fee Fronting | G24: =I24*J13 -> 5448000 | I24: =Ref!D3 -> 0.06
A25: BANK | B25: : | E25: Premi Asuransi | G25: =0.4%*9*J13 -> 3268800 | I25: =0.4%*ROUNDUP(G13/12,0) -> 0.04
A26: JENIS KELAMIN | B26: : | C26: P | E26: Pencadangan | G26: =I26*J13 -> 19522000 | I26: =F19-I24-I25 -> 0.215
